#VRML_SIM R2023b utf8

EXTERNPROTO "https://raw.githubusercontent.com/cyberbotics/webots/R2023b/projects/objects/backgrounds/protos/TexturedBackground.proto"
EXTERNPROTO "https://raw.githubusercontent.com/cyberbotics/webots/R2023b/projects/objects/backgrounds/protos/TexturedBackgroundLight.proto"
EXTERNPROTO "https://raw.githubusercontent.com/cyberbotics/webots/R2023b/projects/objects/floors/protos/RectangleArena.proto"

WorldInfo {
}
Viewpoint {
  orientation 0.1088303362981855 -0.9469266855661255 -0.3024662130949105 5.556906363035311
  position -2.7639923596467244 -1.6461565990884368 3.9182433659641362
}
TexturedBackground {
}
TexturedBackgroundLight {
}
RectangleArena {
  floorSize 10 10
}
Robot {
  translation 0 0 1.5
  rotation 0 1 0 0.785
  children [
    Shape {
      appearance PBRAppearance {
        baseColor 0.403922 0.368627 0.388235
      }
      geometry Box {
        size 0.1 0.1 0.1
      }
    }
    Camera {
      name "Camera"
      width 1920
      height 1080
    }
  ]
  name "cameraRobot"
  controller "cameraController"
}
DEF Markers Pose {
  translation 1.5 0 0.001
  children [
    Solid {
      translation 0 0 0.0001
      rotation 0 0 1 -0.785395307179586
      children [
        Shape {
          appearance PBRAppearance {
            baseColor 0 0 0
            roughness 0.1
            metalness 0
          }
          geometry Plane {
            size 0.05 0.05
          }
        }
      ]
      name "BlackMarker"
    }
    Solid {
      translation 0.5 0.5 0
      children [
        Shape {
          appearance PBRAppearance {
            baseColorMap ImageTexture {
              url [
                "../assets/aruco markers/aruco-marker-ID=0.jpg"
              ]
              repeatS FALSE
              repeatT FALSE
            }
            metalness 0
          }
          geometry Plane {
            size 0.1 0.1
          }
        }
      ]
      name "Marker-0"
    }
    Solid {
      translation 0.5 -0.5 0
      children [
        Shape {
          appearance PBRAppearance {
            baseColorMap ImageTexture {
              url [
                "../assets/aruco markers/aruco-marker-ID=1.jpg"
              ]
              repeatS FALSE
              repeatT FALSE
            }
            metalness 0
          }
          geometry Plane {
            size 0.1 0.1
          }
        }
      ]
      name "Marker-1"
    }
    Solid {
      translation -0.5 0.5 0
      children [
        Shape {
          appearance PBRAppearance {
            baseColorMap ImageTexture {
              url [
                "../assets/aruco markers/aruco-marker-ID=2.jpg"
              ]
              repeatS FALSE
              repeatT FALSE
            }
            metalness 0
          }
          geometry Plane {
            size 0.1 0.1
          }
        }
      ]
      name "Marker-2"
    }
    Solid {
      translation -0.5 -0.5 0
      children [
        Shape {
          appearance PBRAppearance {
            baseColorMap ImageTexture {
              url [
                "../assets/aruco markers/aruco-marker-ID=3.jpg"
              ]
              repeatS FALSE
              repeatT FALSE
            }
            metalness 0
          }
          geometry Plane {
            size 0.1 0.1
          }
        }
      ]
      name "Marker-3"
    }
  ]
}
Solid {
  translation 1.5 -1.49 0.05
  children [
    Shape {
      appearance PBRAppearance {
        baseColor 1 0 0
        roughness 0.2
        metalness 0
      }
      geometry DEF BALL Sphere {
        radius 0.05
        subdivision 2
      }
    }
  ]
  name "Ball"
  boundingObject USE BALL
  physics Physics {
  }
}
Robot {
  translation 1.5 -1.59 0.05
  children [
    SliderJoint {
      jointParameters JointParameters {
        axis 0 1 0
      }
      device [
        LinearMotor {
          name "Launcher"
          maxVelocity 2
          maxForce 100
        }
      ]
      endPoint Solid {
        children [
          DEF smallBOX Shape {
            appearance PBRAppearance {
              baseColor 0.121569 0.0431373 1
              transparency 0.1
              roughness 1
              metalness 0
            }
            geometry Box {
              size 0.09 0.09 0.09
            }
          }
        ]
        boundingObject USE smallBOX
      }
    }
    DEF Launcher Shape {
      appearance PBRAppearance {
        baseColor 0 0 0
      }
      geometry Box {
        size 0.1 0.1 0.1
      }
    }
  ]
  name "Launcher_robot"
  boundingObject USE Launcher
  controller "Launcher"
}
